<?xml version="0.0" ?>
<robot name="blocks">
  <link name="global">
    <inertial>
      <origin rpy="0 0 0" xyz="0 0 0"/>
       <mass value="0"/>
       <inertia ixx="0" ixy="0" ixz="0" iyy="0" iyz="0" izz="0"/>
    </inertial>
  </link>
  <link name="block1">
    <contact>
        <lateral_friction value="1"/>
    </contact>
    <inertial>
      <origin rpy="0 0 0" xyz="0 0 0"/>
      <mass value="0.1"/>
      <inertia ixx="0.1" ixy="0" ixz="0" iyy="0.1" iyz="0" izz="0.1"/>
    </inertial>
    <visual>
      <origin rpy="0 0 0" xyz="0 0 -0.1"/>
      <geometry>
        <box size="2 2 0.2"/>
      </geometry>
      <material name="red">
        <color rgba="0.8 0 0 1"/>
      </material>
    </visual>
    <collision>
      <origin rpy="0 0 0" xyz="0 0 -0.1"/>
      <geometry>
        <box size="2 2 0.2"/>
      </geometry>
    </collision>
  </link>
  <joint name="block1_joint" type="prismatic">
    <parent link="global"/>
    <child link="block1" />
    <axis xyz="0 0 1"/>
    <dynamics spring_refernce="0" spring_stiffness="100000000" friction="0" damping="0"/>
    <limit effort="100000" lower="-0.1" upper="0.1" velocity="5"/>
  </joint>
</robot>

